Workbook

Sheet Comparativa mes año anterior
A1: Comparativa mes año anterior | K1: PIB
B3: Salidas | E3: Llegadas | H3: PASAJEROS TOTALES | N3: promedio | O3: salidas | P3: =AVERAGE(K5:K272) -> 0.50085181
B4: Actual | C4: Año Ant | D4: % Var. Año Ant | E4: Actual | F4: Año Ant | G4: % Var. Año Ant | H4: Actual | I4: Año Ant | J4: % Var. Año Ant | K4: % salidas | L4: % llegadas | O4: llegadas | P4: =AVERAGE(L5:L272) -> 0.49914819
A5: Abr 26 | B5: 31159 | C5: 34373 | D5: -0.093503622 | E5: 31904 | F5: 33270 | G5: -0.04105801 | H5: 63063 | I5: 67643 | J5: -0.06770841 | K5: =B5/H5 -> 0.49409321 | L5: =E5/H5 -> 0.50590679
A6: Mar 26 | B6: 27450 | C6: 26445 | D6: 0.038003403 | E6: 26383 | F6: 25715 | G6: 0.025977056 | H6: 53833 | I6: 52160 | J6: 0.032074387 | K6: =B6/H6 -> 0.50991028 | L6: =E6/H6 -> 0.49008972
A7: Feb 26 | B7: 21719 | C7: 21807 | D7: -0.0040354015 | E7: 21766 | F7: 22052 | G7: -0.012969345 | H7: 43485 | I7: 43859 | J7: -0.0085273262 | K7: =B7/H7 -> 0.49945958 | L7: =E7/H7 -> 0.50054042
A8: Ene 26 | B8: 23695 | C8: 22859 | D8: 0.036572029 | E8: 22640 | F8: 21181 | G8: 0.068882489 | H8: 46335 | I8: 44040 | J8: 0.052111717 | K8: =B8/H8 -> 0.51138448 | L8: =E8/H8 -> 0.48861552
A9: Dic 25 | B9: 25076 | C9: 26713 | D9: -0.061281024 | E9: 26116 | F9: 27911 | G9: -0.064311562 | H9: 51192 | I9: 54624 | J9: -0.062829525 | K9: =B9/H9 -> 0.48984216 | L9: =E9/H9 -> 0.51015784
A10: Nov 25 | B10: 24038 | C10: 24075 | D10: -0.001536864 | E10: 23861 | F10: 24268 | G10: -0.016771057 | H10: 47899 | I10: 48343 | J10: -0.00918437 | K10: =B10/H10 -> 0.50184764 | L10: =E10/H10 -> 0.49815236
A11: Oct 25 | B11: 33094 | C11: 30632 | D11: 0.080373466 | E11: 33174 | F11: 31329 | G11: 0.058891123 | H11: 66268 | I11: 61961 | J11: 0.069511467 | K11: =B11/H11 -> 0.49939639 | L11: =E11/H11 -> 0.50060361
A12: Sep 25 | B12: 30295 | C12: 31254 | D12: -0.030684072 | E12: 32984 | F12: 33370 | G12: -0.011567276 | H12: 63279 | I12: 64624 | J12: -0.020812701 | K12: =B12/H12 -> 0.47875282 | L12: =E12/H12 -> 0.52124718
A13: Ago 25 | B13: 36790 | C13: 35186 | D13: 0.045586313 | E13: 37144 | F13: 35950 | G13: 0.033212796 | H13: 73934 | I13: 71136 | J13: 0.039333108 | K13: =B13/H13 -> 0.49760597 | L13: =E13/H13 -> 0.50239403
A14: Jul 25 | B14: 36520 | C14: 34007 | D14: 0.073896551 | E14: 34544 | F14: 32485 | G14: 0.0633831 | H14: 71064 | I14: 66492 | J14: 0.068760152 | K14: =B14/H14 -> 0.51390296 | L14: =E14/H14 -> 0.48609704
A15: Jun 25 | B15: 31883 | C15: 33781 | D15: -0.05618543 | E15: 29410 | F15: 31224 | G15: -0.058096336 | H15: 61293 | I15: 65005 | J15: -0.0571033 | K15: =B15/H15 -> 0.52017359 | L15: =E15/H15 -> 0.47982641
A16: May 25 | B16: 32119 | C16: 30385 | D16: 0.057067632 | E16: 32743 | F16: 30194 | G16: 0.084420746 | H16: 64862 | I16: 60579 | J16: 0.070701068 | K16: =B16/H16 -> 0.49518979 | L16: =E16/H16 -> 0.50481021
... A56: Ene 22 | B56: 13844 | C56: 2518 | D56: 4.4980143 | E56: 12430 | F56: 2196 | G56: 4.6602914 | H56: 26274 | I56: 4714 | J56: 4.5736105 | K56: =B56/H56 -> 0.52690873 | L56: =E56/H56 -> 0.47309127
A57: Dic 21 | B57: 18941 | C57: =B69 -> 3519 | D57: 0 | E57: 20540 | F57: =E69 -> 3178 | G57: 0 | H57: 39481 | I57: =H69 -> 6697 | J57: 0 | K57: =B57/H57 -> 0.47974975 | L57: =E57/H57 -> 0.52025025
A58: Nov 21 | B58: 17985 | C58: =B70 -> 1289 | D58: 0 | E58: 17867 | F58: =E70 -> 1278 | G58: 0 | H58: 35852 | I58: =H70 -> 2567 | J58: 0 | K58: =B58/H58 -> 0.50164565 | L58: =E58/H58 -> 0.49835435
A59: Oct 21 | B59: 15294 | C59: =B71 -> 4105 | D59: 0 | E59: 16196 | F59: =E71 -> 4367 | G59: 0 | H59: 31490 | I59: =H71 -> 8472 | J59: 0 | K59: =B59/H59 -> 0.48567799 | L59: =E59/H59 -> 0.51432201
A60: Sep 21 | B60: 17328 | C60: =B72 -> 7702 | D60: 0 | E60: 20517 | F60: =E72 -> 9402 | G60: 0 | H60: 37845 | I60: =H72 -> 17104 | J60: 0 | K60: =B60/H60 -> 0.45786762 | L60: =E60/H60 -> 0.54213238
A61: Ago 21 | B61: 24809 | C61: =B73 -> 16485 | D61: 0 | E61: 25022 | F61: =E73 -> 15993 | G61: 0 | H61: 49831 | I61: =H73 -> 32478 | J61: 0 | K61: =B61/H61 -> 0.49786278 | L61: =E61/H61 -> 0.50213722
A62: Jul 21 | B62: 21330 | C62: =B74 -> 12127 | D62: 0 | E62: 18918 | F62: =E74 -> 10299 | G62: 0 | H62: 40248 | I62: =H74 -> 22426 | J62: 0 | K62: =B62/H62 -> 0.52996422 | L62: =E62/H62 -> 0.47003578
A63: Jun 21 | B63: 11332 | C63: =B75 -> 353 | D63: 0 | E63: 8765 | F63: =E75 -> 261 | G63: 0 | H63: 20097 | I63: =H75 -> 614 | J63: 0 | K63: =B63/H63 -> 0.56386525 | L63: =E63/H63 -> 0.43613475
A64: May 21 | B64: 4752 | C64: =B76 -> 20 | D64: 0 | E64: 4202 | F64: =E76 -> 20 | G64: 0 | H64: 8954 | I64: =H76 -> 40 | J64: 0 | K64: =B64/H64 -> 0.53071253 | L64: =E64/H64 -> 0.46928747
A65: Abr 21 | B65: 2872 | C65: =B77 -> 0 | D65: 0 | E65: 2325 | F65: =E77 -> 4 | G65: 0 | H65: 5197 | I65: =H77 -> 4 | J65: 0 | K65: =B65/H65 -> 0.55262652 | L65: =E65/H65 -> 0.44737348
A66: Mar 21 | B66: 1620 | C66: =B78 -> 7014 | D66: 0 | E66: 1539 | F66: =E78 -> 7574 | G66: 0 | H66: 3159 | I66: =H78 -> 14588 | J66: 0 | K66: =B66/H66 -> 0.51282051 | L66: =E66/H66 -> 0.48717949
A67: Feb 21 | B67: 717 | C67: =B79 -> 16111 | D67: 0 | E67: 864 | F67: =E79 -> 16380 | G67: 0 | H67: 1581 | I67: =H79 -> 32491 | J67: 0 | K67: =B67/H67 -> 0.45351044 | L67: =E67/H67 -> 0.54648956
A68: Ene 21 | B68: 2518 | C68: =B80 -> 17459 | D68: 0 | E68: 2196 | F68: =E80 -> 15591 | G68: 0 | H68: 4714 | I68: =H80 -> 33050 | J68: 0 | K68: =B68/H68 -> 0.53415359 | L68: =E68/H68 -> 0.46584641
A69: 44166 | B69: 3519 | C69: =B81 -> 13724 | D69: =ABS(B69-C69)/C69 -> 0.74358788 | E69: 3178 | F69: =E81 -> 14374 | G69: =ABS(E69-F69)/F69 -> 0.77890636 | H69: =B69+E69 -> 6697 | I69: =H81 -> 28098 | J69: =ABS(H69-I69)/I69 -> 0.76165563 | K69: =B69/H69 -> 0.52545916 | L69: =E69/H69 -> 0.47454084
A70: 44136 | B70: 1289 | C70: =B82 -> 12572 | D70: =ABS(B70-C70)/C70 -> 0.89747057 | E70: 1278 | F70: =E82 -> 11668 | G70: =ABS(E70-F70)/F70 -> 0.89046966 | H70: =B70+E70 -> 2567 | I70: =H82 -> 24240 | J70: =ABS(H70-I70)/I70 -> 0.89410066 | K70: =B70/H70 -> 0.50214258 | L70: =E70/H70 -> 0.49785742
A71: 44105 | B71: 4105 | C71: =B83 -> 14700 | D71: =ABS(B71-C71)/C71 -> 0.7207483 | E71: 4367 | F71: =E83 -> 14554 | G71: =ABS(E71-F71)/F71 -> 0.69994503 | H71: =B71+E71 -> 8472 | I71: =H83 -> 29254 | J71: =ABS(H71-I71)/I71 -> 0.71039858 | K71: =B71/H71 -> 0.4845373 | L71: =E71/H71 -> 0.5154627
A72: 44075 | B72: 7702 | C72: =B84 -> 17302 | D72: =ABS(B72-C72)/C72 -> 0.55484915 | E72: 9402 | F72: =E84 -> 17453 | G72: =ABS(E72-F72)/F72 -> 0.46129605 | H72: =B72+E72 -> 17104 | I72: =H84 -> 34755 | J72: =ABS(H72-I72)/I72 -> 0.50786937 | K72: =B72/H72 -> 0.45030402 | L72: =E72/H72 -> 0.54969598
A73: 44044 | B73: 16485 | C73: =B85 -> 19108 | D73: =ABS(B73-C73)/C73 -> 0.13727235 | E73: 15993 | F73: =E85 -> 18616 | G73: =ABS(E73-F73)/F73 -> 0.1409003 | H73: =B73+E73 -> 32478 | I73: =H85 -> 37724 | J73: =ABS(H73-I73)/I73 -> 0.13906267 | K73: =B73/H73 -> 0.50757436 | L73: =E73/H73 -> 0.49242564
A74: 44013 | B74: 12127 | C74: =B86 -> 19649 | D74: =ABS(B74-C74)/C74 -> 0.38281846 | E74: 10299 | F74: =E86 -> 19492 | G74: =ABS(E74-F74)/F74 -> 0.47162939 | H74: =B74+E74 -> 22426 | I74: =H86 -> 39141 | J74: =ABS(H74-I74)/I74 -> 0.42704581 | K74: =B74/H74 -> 0.54075627 | L74: =E74/H74 -> 0.45924373
A75: 43983 | B75: 353 | C75: =B87 -> 16767 | D75: =ABS(B75-C75)/C75 -> 0.97894674 | E75: 261 | F75: =E87 -> 15297 | G75: =ABS(E75-F75)/F75 -> 0.98293783 | H75: =B75+E75 -> 614 | I75: =H87 -> 32064 | J75: =ABS(H75-I75)/I75 -> 0.9808508 | K75: =B75/H75 -> 0.57491857 | L75: =E75/H75 -> 0.42508143
A76: 43952 | B76: 20 | C76: =B88 -> 13142 | D76: =ABS(B76-C76)/C76 -> 0.99847816 | E76: 20 | F76: =E88 -> 13282 | G76: =ABS(E76-F76)/F76 -> 0.9984942 | H76: =B76+E76 -> 40 | I76: =H88 -> 26424 | J76: =ABS(H76-I76)/I76 -> 0.99848622 | K76: =B76/H76 -> 0.5 | L76: =E76/H76 -> 0.5
A77: 43922 | B77: 0 | C77: =B89 -> 14930 | D77: =ABS(B77-C77)/C77 -> 1 | E77: 4 | F77: =E89 -> 14693 | G77: =ABS(E77-F77)/F77 -> 0.99972776 | H77: =B77+E77 -> 4 | I77: =H89 -> 29623 | J77: =ABS(H77-I77)/I77 -> 0.99986497 | K77: =B77/H77 -> 0 | L77: =E77/H77 -> 1
A78: 43891 | B78: 7014 | C78: =B90 -> 11409 | D78: =ABS(B78-C78)/C78 -> 0.38522219 | E78: 7574 | F78: =E90 -> 11192 | G78: =ABS(E78-F78)/F78 -> 0.32326662 | H78: =B78+E78 -> 14588 | I78: =H90 -> 22601 | J78: =ABS(H78-I78)/I78 -> 0.35454183 | K78: =B78/H78 -> 0.48080614 | L78: =E78/H78 -> 0.51919386
A79: 43862 | B79: 16111 | C79: =B91 -> 9620 | D79: =ABS(B79-C79)/C79 -> 0.67474012 | E79: 16380 | F79: =E91 -> 9718 | G79: =ABS(E79-F79)/F79 -> 0.685532 | H79: =B79+E79 -> 32491 | I79: =H91 -> 19338 | J79: =ABS(H79-I79)/I79 -> 0.68016341 | K79: =B79/H79 -> 0.49586039 | L79: =E79/H79 -> 0.50413961
A80: 43831 | B80: 17459 | C80: =B92 -> 11167 | D80: =ABS(B80-C80)/C80 -> 0.56344587 | E80: 15591 | F80: =E92 -> 10549 | G80: =ABS(E80-F80)/F80 -> 0.47796 | H80: =B80+E80 -> 33050 | I80: =H92 -> 21716 | J80: =ABS(H80-I80)/I80 -> 0.52191932 | K80: =B80/H80 -> 0.52826021 | L80: =E80/H80 -> 0.47173979
...

Sheet Análisis tendencia
H1: PIB
A4: Año | B4: Mes | C4: Trimestre | D4: fecha | E4: Salidas | F4: Llegadas | G4: Pasajeros | H4: % salidas | I4: % llegadas | J4: Media móvil salidas | K4: media móvil llegadas | L4: Media móvil total | M4: índice estacional salidas | N4: índice estacional llegadas | O4: índice estacional total
A5: 26 | B5: Abr | C5: T2 | D5: Abr 26 | E5: 31159 | F5: 31904 | G5: 63063 | H5: =E5/G5 -> 0.49409321 | I5: =F5/G5 -> 0.50590679
A6: 26 | B6: Mar | C6: T1 | D6: Mar 26 | E6: 27450 | F6: 26383 | G6: 53833 | H6: =E6/G6 -> 0.50991028 | I6: =F6/G6 -> 0.49008972
A7: 26 | B7: Feb | C7: T1 | D7: Feb 26 | E7: 21719 | F7: 21766 | G7: 43485 | H7: =E7/G7 -> 0.49945958 | I7: =F7/G7 -> 0.50054042
A8: 26 | B8: Ene | C8: T1 | D8: Ene 26 | E8: 23695 | F8: 22640 | G8: 46335 | H8: =E8/G8 -> 0.51138448 | I8: =F8/G8 -> 0.48861552
A9: 25 | B9: Dic | C9: T4 | D9: Dic 25 | E9: 25076 | F9: 26116 | G9: 51192 | H9: =E9/G9 -> 0.48984216 | I9: =F9/G9 -> 0.51015784
A10: 25 | B10: Nov | C10: T4 | D10: Nov 25 | E10: 24038 | F10: 23861 | G10: 47899 | H10: =E10/G10 -> 0.50184764 | I10: =F10/G10 -> 0.49815236
A11: 25 | B11: Oct | C11: T4 | D11: Oct 25 | E11: 33094 | F11: 33174 | G11: 66268 | H11: =E11/G11 -> 0.49939639 | I11: =F11/G11 -> 0.50060361 | J11: =(0.5*E5+E6+E7+E8+E9+E10+E11+E12+E13+E14+E15+E16+E17*0.5)/12 -> 29620.417 | K11: =(0.5*F5+F6+F7+F8+F9+F10+F11+F12+F13+F14+F15+F16+F17*0.5)/12 -> 29446 | L11: =(0.5*G5+G6+G7+G8+G9+G10+G11+G12+G13+G14+G15+G16+G17*0.5)/12 -> 59066.417 | M11: =E11/J11 -> 1.1172699 | N11: =F11/K11 -> 1.1266046 | O11: =G11/L11 -> 1.1219235
A12: 25 | B12: Sep | C12: T3 | D12: Sep 25 | E12: 30295 | F12: 32984 | G12: 63279 | H12: =E12/G12 -> 0.47875282 | I12: =F12/G12 -> 0.52124718 | J12: =(0.5*E6+E7+E8+E9+E10+E11+E12+E13+E14+E15+E16+E17+E18*0.5)/12 -> 29712.458 | K12: =(0.5*F6+F7+F8+F9+F10+F11+F12+F13+F14+F15+F16+F17+F18*0.5)/12 -> 29475.083 | L12: =(0.5*G6+G7+G8+G9+G10+G11+G12+G13+G14+G15+G16+G17+G18*0.5)/12 -> 59187.542 | M12: =E12/J12 -> 1.019606 | N12: =F12/K12 -> 1.1190469 | O12: =G12/L12 -> 1.069127
A13: 25 | B13: Ago | C13: T3 | D13: Ago 25 | E13: 36790 | F13: 37144 | G13: 73934 | H13: =E13/G13 -> 0.49760597 | I13: =F13/G13 -> 0.50239403 | J13: =(0.5*E7+E8+E9+E10+E11+E12+E13+E14+E15+E16+E17+E18+E19*0.5)/12 -> 29674.25 | K13: =(0.5*F7+F8+F9+F10+F11+F12+F13+F14+F15+F16+F17+F18+F19*0.5)/12 -> 29459.167 | L13: =(0.5*G7+G8+G9+G10+G11+G12+G13+G14+G15+G16+G17+G18+G19*0.5)/12 -> 59133.417 | M13: =E13/J13 -> 1.2397954 | N13: =F13/K13 -> 1.2608639 | O13: =G13/L13 -> 1.2502914
A14: 25 | B14: Jul | C14: T3 | D14: Jul 25 | E14: 36520 | F14: 34544 | G14: 71064 | H14: =E14/G14 -> 0.51390296 | I14: =F14/G14 -> 0.48609704 | J14: =(0.5*E8+E9+E10+E11+E12+E13+E14+E15+E16+E17+E18+E19+E20*0.5)/12 -> 29643.083 | K14: =(0.5*F8+F9+F10+F11+F12+F13+F14+F15+F16+F17+F18+F19+F20*0.5)/12 -> 29410.292 | L14: =(0.5*G8+G9+G10+G11+G12+G13+G14+G15+G16+G17+G18+G19+G20*0.5)/12 -> 59053.375 | M14: =E14/J14 -> 1.2319906 | N14: =F14/K14 -> 1.1745548 | O14: =G14/L14 -> 1.2033859
A15: 25 | B15: Jun | C15: T2 | D15: Jun 25 | E15: 31883 | F15: 29410 | G15: 61293 | H15: =E15/G15 -> 0.52017359 | I15: =F15/G15 -> 0.47982641 | J15: =(0.5*E9+E10+E11+E12+E13+E14+E15+E16+E17+E18+E19+E20+E21*0.5)/12 -> 29676.458 | K15: =(0.5*F9+F10+F11+F12+F13+F14+F15+F16+F17+F18+F19+F20+F21*0.5)/12 -> 29424.292 | L15: =(0.5*G9+G10+G11+G12+G13+G14+G15+G16+G17+G18+G19+G20+G21*0.5)/12 -> 59100.75 | M15: =E15/J15 -> 1.0743533 | N15: =F15/K15 -> 0.99951429 | O15: =G15/L15 -> 1.0370934
A16: 25 | B16: May | C16: T2 | D16: May 25 | E16: 32119 | F16: 32743 | G16: 64862 | H16: =E16/G16 -> 0.49518979 | I16: =F16/G16 -> 0.50481021 | J16: =(0.5*E10+E11+E12+E13+E14+E15+E16+E17+E18+E19+E20+E21+E22*0.5)/12 -> 29746.208 | K16: =(0.5*F10+F11+F12+F13+F14+F15+F16+F17+F18+F19+F20+F21+F22*0.5)/12 -> 29516.042 | L16: =(0.5*G10+G11+G12+G13+G14+G15+G16+G17+G18+G19+G20+G21+G22*0.5)/12 -> 59262.25 | M16: =E16/J16 -> 1.0797679 | N16: =F16/K16 -> 1.109329 | O16: =G16/L16 -> 1.094491
A17: 25 | B17: Abr | C17: T2 | D17: Abr 25 | E17: 34373 | F17: 33270 | G17: 67643 | H17: =E17/G17 -> 0.5081531 | I17: =F17/G17 -> 0.4918469 | J17: =(0.5*E11+E12+E13+E14+E15+E16+E17+E18+E19+E20+E21+E22+E23*0.5)/12 -> 29645.167 | K17: =(0.5*F11+F12+F13+F14+F15+F16+F17+F18+F19+F20+F21+F22+F23*0.5)/12 -> 29456.125 | L17: =(0.5*G11+G12+G13+G14+G15+G16+G17+G18+G19+G20+G21+G22+G23*0.5)/12 -> 59101.292 | M17: =E17/J17 -> 1.1594807 | N17: =F17/K17 -> 1.1294765 | O17: =G17/L17 -> 1.1445266
A18: 25 | B18: Mar | C18: T1 | D18: Mar 25 | E18: 26445 | F18: 25715 | G18: 52160 | H18: =E18/G18 -> 0.5069977 | I18: =F18/G18 -> 0.4930023 | J18: =(0.5*E12+E13+E14+E15+E16+E17+E18+E19+E20+E21+E22+E23+E24*0.5)/12 -> 29582.542 | K18: =(0.5*F12+F13+F14+F15+F16+F17+F18+F19+F20+F21+F22+F23+F24*0.5)/12 -> 29395.333 | L18: =(0.5*G12+G13+G14+G15+G16+G17+G18+G19+G20+G21+G22+G23+G24*0.5)/12 -> 58977.875 | M18: =E18/J18 -> 0.89393942 | N18: =F18/K18 -> 0.87479872 | O18: =G18/L18 -> 0.88439945
A19: 25 | B19: Feb | C19: T1 | D19: Feb 25 | E19: 21807 | F19: 22052 | G19: 43859 | H19: =E19/G19 -> 0.49720696 | I19: =F19/G19 -> 0.50279304 | J19: =(0.5*E13+E14+E15+E16+E17+E18+E19+E20+E21+E22+E23+E24+E25*0.5)/12 -> 29555.667 | K19: =(0.5*F13+F14+F15+F16+F17+F18+F19+F20+F21+F22+F23+F24+F25*0.5)/12 -> 29361.667 | L19: =(0.5*G13+G14+G15+G16+G17+G18+G19+G20+G21+G22+G23+G24+G25*0.5)/12 -> 58917.333 | M19: =E19/J19 -> 0.73782805 | N19: =F19/K19 -> 0.75104728 | O19: =G19/L19 -> 0.7444159
A20: 25 | B20: Ene | C20: T1 | D20: Ene 25 | E20: 22859 | F20: 21181 | G20: 44040 | H20: =E20/G20 -> 0.51905086 | I20: =F20/G20 -> 0.48094914 | J20: =(0.5*E14+E15+E16+E17+E18+E19+E20+E21+E22+E23+E24+E25+E26*0.5)/12 -> 29384.125 | K20: =(0.5*F14+F15+F16+F17+F18+F19+F20+F21+F22+F23+F24+F25+F26*0.5)/12 -> 29226.125 | L20: =(0.5*G14+G15+G16+G17+G18+G19+G20+G21+G22+G23+G24+G25+G26*0.5)/12 -> 58610.25 | M20: =E20/J20 -> 0.77793707 | N20: =F20/K20 -> 0.7247283 | O20: =G20/L20 -> 0.7514044
A21: 24 | B21: Dic | C21: T4 | D21: Dic 24 | E21: 26713 | F21: 27911 | G21: 54624 | H21: =E21/G21 -> 0.48903412 | I21: =F21/G21 -> 0.51096588 | J21: =(0.5*E15+E16+E17+E18+E19+E20+E21+E22+E23+E24+E25+E26+E27*0.5)/12 -> 29358.5 | K21: =(0.5*F15+F16+F17+F18+F19+F20+F21+F22+F23+F24+F25+F26+F27*0.5)/12 -> 29215.917 | L21: =(0.5*G15+G16+G17+G18+G19+G20+G21+G22+G23+G24+G25+G26+G27*0.5)/12 -> 58574.417 | M21: =E21/J21 -> 0.90988981 | N21: =F21/K21 -> 0.95533542 | O21: =G21/L21 -> 0.9325573
A22: 24 | B22: Nov | C22: T4 | D22: Nov 24 | E22: 24075 | F22: 24268 | G22: 48343 | H22: =E22/G22 -> 0.49800385 | I22: =F22/G22 -> 0.50199615 | J22: =(0.5*E16+E17+E18+E19+E20+E21+E22+E23+E24+E25+E26+E27+E28*0.5)/12 -> 29365.333 | K22: =(0.5*F16+F17+F18+F19+F20+F21+F22+F23+F24+F25+F26+F27+F28*0.5)/12 -> 29185.292 | L22: =(0.5*G16+G17+G18+G19+G20+G21+G22+G23+G24+G25+G26+G27+G28*0.5)/12 -> 58550.625 | M22: =E22/J22 -> 0.81984426 | N22: =F22/K22 -> 0.83151473 | O22: =G22/L22 -> 0.82566155
... A31: 24 | B31: Feb | C31: T1 | D31: Feb 24 | E31: 20941 | F31: 20982 | G31: 41923 | H31: =E31/G31 -> 0.49951101 | I31: =F31/G31 -> 0.50048899 | J31: =(0.5*E25+E26+E27+E28+E29+E30+E31+E32+E33+E34+E35+E36+E37*0.5)/12 -> 28382.542 | K31: =(0.5*F25+F26+F27+F28+F29+F30+F31+F32+F33+F34+F35+F36+F37*0.5)/12 -> 28112.125 | L31: =(0.5*G25+G26+G27+G28+G29+G30+G31+G32+G33+G34+G35+G36+G37*0.5)/12 -> 56494.667 | M31: =E31/J31 -> 0.73781271 | N31: =F31/K31 -> 0.74636834 | O31: =G31/L31 -> 0.74207005
A32: 24 | B32: Ene | C32: T1 | D32: Ene 24 | E32: 23338 | F32: 22113 | G32: 45451 | H32: =E32/G32 -> 0.51347605 | I32: =F32/G32 -> 0.48652395 | J32: =(0.5*E26+E27+E28+E29+E30+E31+E32+E33+E34+E35+E36+E37+E38*0.5)/12 -> 28529.75 | K32: =(0.5*F26+F27+F28+F29+F30+F31+F32+F33+F34+F35+F36+F37+F38*0.5)/12 -> 28245.542 | L32: =(0.5*G26+G27+G28+G29+G30+G31+G32+G33+G34+G35+G36+G37+G38*0.5)/12 -> 56775.292 | M32: =E32/J32 -> 0.81802329 | N32: =F32/K32 -> 0.78288461 | O32: =G32/L32 -> 0.8005419 | AV32: promedio | AW32: salidas | AX32: 0.502
A33: 23 | B33: Dic | C33: T4 | D33: Dic 23 | E33: 24925 | F33: 25139 | G33: 50064 | H33: =E33/G33 -> 0.49786274 | I33: =F33/G33 -> 0.50213726 | J33: =(0.5*E27+E28+E29+E30+E31+E32+E33+E34+E35+E36+E37+E38+E39*0.5)/12 -> 28479.958 | K33: =(0.5*F27+F28+F29+F30+F31+F32+F33+F34+F35+F36+F37+F38+F39*0.5)/12 -> 28225.208 | L33: =(0.5*G27+G28+G29+G30+G31+G32+G33+G34+G35+G36+G37+G38+G39*0.5)/12 -> 56705.167 | M33: =E33/J33 -> 0.87517684 | N33: =F33/K33 -> 0.89065773 | O33: =G33/L33 -> 0.88288251 | AW33: llegadas | AX33: 0.498
A34: 23 | B34: Nov | C34: T4 | D34: Nov 23 | E34: 20567 | F34: 19967 | G34: 40534 | H34: =E34/G34 -> 0.50740119 | I34: =F34/G34 -> 0.49259881 | J34: =(0.5*E28+E29+E30+E31+E32+E33+E34+E35+E36+E37+E38+E39+E40*0.5)/12 -> 28218 | K34: =(0.5*F28+F29+F30+F31+F32+F33+F34+F35+F36+F37+F38+F39+F40*0.5)/12 -> 27957.583 | L34: =(0.5*G28+G29+G30+G31+G32+G33+G34+G35+G36+G37+G38+G39+G40*0.5)/12 -> 56175.583 | M34: =E34/J34 -> 0.72886101 | N34: =F34/K34 -> 0.71418905 | O34: =G34/L34 -> 0.72155904
A35: 23 | B35: Oct | C35: T4 | D35: Oct 23 | E35: 29371 | F35: 30350 | G35: 59721 | H35: =E35/G35 -> 0.49180355 | I35: =F35/G35 -> 0.50819645 | J35: =(0.5*E29+E30+E31+E32+E33+E34+E35+E36+E37+E38+E39+E40+E41*0.5)/12 -> 28207.167 | K35: =(0.5*F29+F30+F31+F32+F33+F34+F35+F36+F37+F38+F39+F40+F41*0.5)/12 -> 27921.208 | L35: =(0.5*G29+G30+G31+G32+G33+G34+G35+G36+G37+G38+G39+G40+G41*0.5)/12 -> 56128.375 | M35: =E35/J35 -> 1.0412602 | N35: =F35/K35 -> 1.0869873 | O35: =G35/L35 -> 1.0640073
A36: 23 | B36: Sep | C36: T3 | D36: Sep 23 | E36: 30245 | F36: 31757 | G36: 62002 | H36: =E36/G36 -> 0.48780684 | I36: =F36/G36 -> 0.51219316 | J36: =(0.5*E30+E31+E32+E33+E34+E35+E36+E37+E38+E39+E40+E41+E42*0.5)/12 -> 28325.833 | K36: =(0.5*F30+F31+F32+F33+F34+F35+F36+F37+F38+F39+F40+F41+F42*0.5)/12 -> 27989.208 | L36: =(0.5*G30+G31+G32+G33+G34+G35+G36+G37+G38+G39+G40+G41+G42*0.5)/12 -> 56315.042 | M36: =E36/J36 -> 1.0677532 | N36: =F36/K36 -> 1.1346159 | O36: =G36/L36 -> 1.1009847
A37: 23 | B37: Ago | C37: T3 | D37: Ago 23 | E37: 36717 | F37: 36279 | G37: 72996 | H37: =E37/G37 -> 0.50300016 | I37: =F37/G37 -> 0.49699984 | J37: =(0.5*E31+E32+E33+E34+E35+E36+E37+E38+E39+E40+E41+E42+E43*0.5)/12 -> 28396.583 | K37: =(0.5*F31+F32+F33+F34+F35+F36+F37+F38+F39+F40+F41+F42+F43*0.5)/12 -> 28074.708 | L37: =(0.5*G31+G32+G33+G34+G35+G36+G37+G38+G39+G40+G41+G42+G43*0.5)/12 -> 56471.292 | M37: =E37/J37 -> 1.2930077 | N37: =F37/K37 -> 1.2922307 | O37: =G37/L37 -> 1.2926214
A38: 23 | B38: Jul | C38: T3 | D38: Jul 23 | E38: 36009 | F38: 35358 | G38: 71367 | H38: =E38/G38 -> 0.50456093 | I38: =F38/G38 -> 0.49543907 | J38: =(0.5*E32+E33+E34+E35+E36+E37+E38+E39+E40+E41+E42+E43+E44*0.5)/12 -> 28572.75 | K38: =(0.5*F32+F33+F34+F35+F36+F37+F38+F39+F40+F41+F42+F43+F44*0.5)/12 -> 28322.667 | L38: =(0.5*G32+G33+G34+G35+G36+G37+G38+G39+G40+G41+G42+G43+G44*0.5)/12 -> 56895.417 | M38: =E38/J38 -> 1.2602567 | N38: =F38/K38 -> 1.2483994 | O38: =G38/L38 -> 1.2543541
A39: 23 | B39: Jun | C39: T2 | D39: Jun 23 | E39: 30584 | F39: 27863 | G39: 58447 | H39: =E39/G39 -> 0.5232775 | I39: =F39/G39 -> 0.4767225 | J39: =(0.5*E33+E34+E35+E36+E37+E38+E39+E40+E41+E42+E43+E44+E45*0.5)/12 -> 28753 | K39: =(0.5*F33+F34+F35+F36+F37+F38+F39+F40+F41+F42+F43+F44+F45*0.5)/12 -> 28566.042 | L39: =(0.5*G33+G34+G35+G36+G37+G38+G39+G40+G41+G42+G43+G44+G45*0.5)/12 -> 57319.042 | M39: =E39/J39 -> 1.0636803 | N39: =F39/K39 -> 0.9753889 | O39: =G39/L39 -> 1.0196786
A40: 23 | B40: May | C40: T2 | D40: May 23 | E40: 27295 | F40: 27132 | G40: 54427 | H40: =E40/G40 -> 0.50149742 | I40: =F40/G40 -> 0.49850258 | J40: =(0.5*E34+E35+E36+E37+E38+E39+E40+E41+E42+E43+E44+E45+E46*0.5)/12 -> 28919.292 | K40: =(0.5*F34+F35+F36+F37+F38+F39+F40+F41+F42+F43+F44+F45+F46*0.5)/12 -> 28760.708 | L40: =(0.5*G34+G35+G36+G37+G38+G39+G40+G41+G42+G43+G44+G45+G46*0.5)/12 -> 57680 | M40: =E40/J40 -> 0.94383363 | N40: =F40/K40 -> 0.94337037 | O40: =G40/L40 -> 0.94360264
A41: 23 | B41: Abr | C41: T2 | D41: Abr 23 | E41: 32288 | F41: 32260 | G41: 64548 | H41: =E41/G41 -> 0.50021689 | I41: =F41/G41 -> 0.49978311 | J41: =(0.5*E35+E36+E37+E38+E39+E40+E41+E42+E43+E44+E45+E46+E47*0.5)/12 -> 29009.083 | K41: =(0.5*F35+F36+F37+F38+F39+F40+F41+F42+F43+F44+F45+F46+F47*0.5)/12 -> 28817.417 | L41: =(0.5*G35+G36+G37+G38+G39+G40+G41+G42+G43+G44+G45+G46+G47*0.5)/12 -> 57826.5 | M41: =E41/J41 -> 1.1130307 | N41: =F41/K41 -> 1.1194619 | O41: =G41/L41 -> 1.1162356
A42: 23 | B42: Mar | C42: T1 | D42: Mar 23 | E42: 27639 | F42: 26392 | G42: 54031 | H42: =E42/G42 -> 0.51153967 | I42: =F42/G42 -> 0.48846033 | J42: =(0.5*E36+E37+E38+E39+E40+E41+E42+E43+E44+E45+E46+E47+E48*0.5)/12 -> 28987.958 | K42: =(0.5*F36+F37+F38+F39+F40+F41+F42+F43+F44+F45+F46+F47+F48*0.5)/12 -> 28772.167 | L42: =(0.5*G36+G37+G38+G39+G40+G41+G42+G43+G44+G45+G46+G47+G48*0.5)/12 -> 57760.125 | M42: =E42/J42 -> 0.95346487 | N42: =F42/K42 -> 0.91727538 | O42: =G42/L42 -> 0.93543773
A43: 23 | B43: Feb | C43: T1 | D43: Feb 23 | E43: 22621 | F43: 23591 | G43: 46212 | H43: =E43/G43 -> 0.48950489 | I43: =F43/G43 -> 0.51049511 | J43: =(0.5*E37+E38+E39+E40+E41+E42+E43+E44+E45+E46+E47+E48+E49*0.5)/12 -> 28951.708 | K43: =(0.5*F37+F38+F39+F40+F41+F42+F43+F44+F45+F46+F47+F48+F49*0.5)/12 -> 28743.125 | L43: =(0.5*G37+G38+G39+G40+G41+G42+G43+G44+G45+G46+G47+G48+G49*0.5)/12 -> 57694.833 | M43: =E43/J43 -> 0.78133559 | N43: =F43/K43 -> 0.82075279 | O43: =G43/L43 -> 0.80097294
A44: 23 | B44: Ene | C44: T1 | D44: Ene 23 | E44: 25886 | F44: 25455 | G44: 51341 | H44: =E44/G44 -> 0.50419743 | I44: =F44/G44 -> 0.49580257 | J44: =(0.5*E38+E39+E40+E41+E42+E43+E44+E45+E46+E47+E48+E49+E50*0.5)/12 -> 28898 | K44: =(0.5*F38+F39+F40+F41+F42+F43+F44+F45+F46+F47+F48+F49+F50*0.5)/12 -> 28683.167 | L44: =(0.5*G38+G39+G40+G41+G42+G43+G44+G45+G46+G47+G48+G49+G50*0.5)/12 -> 57581.167 | M44: =E44/J44 -> 0.89577133 | N44: =F44/K44 -> 0.88745431 | O44: =G44/L44 -> 0.89162834
A45: 22 | B45: Dic | C45: T4 | D45: Dic 22 | E45: 26703 | F45: 27638 | G45: 54341 | H45: =E45/G45 -> 0.49139692 | I45: =F45/G45 -> 0.50860308 | J45: =(0.5*E39+E40+E41+E42+E43+E44+E45+E46+E47+E48+E49+E50+E51*0.5)/12 -> 28969.375 | K45: =(0.5*F39+F40+F41+F42+F43+F44+F45+F46+F47+F48+F49+F50+F51*0.5)/12 -> 28692.125 | L45: =(0.5*G39+G40+G41+G42+G43+G44+G45+G46+G47+G48+G49+G50+G51*0.5)/12 -> 57661.5 | M45: =E45/J45 -> 0.92176652 | N45: =F45/K45 -> 0.96326083 | O45: =G45/L45 -> 0.94241392
... A56: 22 | B56: Ene | C56: T1 | D56: Ene 22 | E56: 13844 | F56: 12430 | G56: 26274 | H56: =E56/G56 -> 0.52690873 | I56: =F56/G56 -> 0.47309127 | J56: =(0.5*E50+E51+E52+E53+E54+E55+E56+E57+E58+E59+E60+E61+E62*0.5)/12 -> 20080.167 | K56: =(0.5*F50+F51+F52+F53+F54+F55+F56+F57+F58+F59+F60+F61+F62*0.5)/12 -> 19519.333 | L56: =(0.5*G50+G51+G52+G53+G54+G55+G56+G57+G58+G59+G60+G61+G62*0.5)/12 -> 39599.5 | M56: =E56/J56 -> 0.68943651 | N56: =F56/K56 -> 0.63680454 | O56: =G56/L56 -> 0.66349323
A57: 19 | B57: dic | C57: T4 | D57: 43800 | E57: 13724 | F57: 14374 | G57: =E57+F57 -> 28098 | H57: =E57/G57 -> 0.48843334 | I57: =F57/G57 -> 0.51156666 | J57: =(0.5*E51+E52+E53+E54+E55+E56+E57+E58+E59+E60+E61+E62+E63*0.5)/12 -> 18751.417 | K57: =(0.5*F51+F52+F53+F54+F55+F56+F57+F58+F59+F60+F61+F62+F63*0.5)/12 -> 18325.708 | L57: =(0.5*G51+G52+G53+G54+G55+G56+G57+G58+G59+G60+G61+G62+G63*0.5)/12 -> 37077.125 | M57: =E57/J57 -> 0.73189137 | N57: =F57/K57 -> 0.78436259 | O57: =G57/L57 -> 0.75782575
A58: 19 | B58: nov | C58: T4 | D58: 43770 | E58: 12572 | F58: 11668 | G58: =E58+F58 -> 24240 | H58: =E58/G58 -> 0.51864686 | I58: =F58/G58 -> 0.48135314 | J58: =(0.5*E52+E53+E54+E55+E56+E57+E58+E59+E60+E61+E62+E63+E64*0.5)/12 -> 17558.375 | K58: =(0.5*F52+F53+F54+F55+F56+F57+F58+F59+F60+F61+F62+F63+F64*0.5)/12 -> 17233.167 | L58: =(0.5*G52+G53+G54+G55+G56+G57+G58+G59+G60+G61+G62+G63+G64*0.5)/12 -> 34791.542 | M58: =E58/J58 -> 0.71601159 | N58: =F58/K58 -> 0.67706651 | O58: =G58/L58 -> 0.69672107
A59: 19 | B59: oct | C59: T4 | D59: 43739 | E59: 14700 | F59: 14554 | G59: =E59+F59 -> 29254 | H59: =E59/G59 -> 0.50249539 | I59: =F59/G59 -> 0.49750461 | J59: =(0.5*E53+E54+E55+E56+E57+E58+E59+E60+E61+E62+E63+E64+E65*0.5)/12 -> 16543.75 | K59: =(0.5*F53+F54+F55+F56+F57+F58+F59+F60+F61+F62+F63+F64+F65*0.5)/12 -> 16248.208 | L59: =(0.5*G53+G54+G55+G56+G57+G58+G59+G60+G61+G62+G63+G64+G65*0.5)/12 -> 32791.958 | M59: =E59/J59 -> 0.88855308 | N59: =F59/K59 -> 0.89572953 | O59: =G59/L59 -> 0.89210896
A60: 19 | B60: sep | C60: T3 | D60: 43709 | E60: 17302 | F60: 17453 | G60: =E60+F60 -> 34755 | H60: =E60/G60 -> 0.49782765 | I60: =F60/G60 -> 0.50217235 | J60: =(0.5*E54+E55+E56+E57+E58+E59+E60+E61+E62+E63+E64+E65+E66*0.5)/12 -> 15581.542 | K60: =(0.5*F54+F55+F56+F57+F58+F59+F60+F61+F62+F63+F64+F65+F66*0.5)/12 -> 15320.875 | L60: =(0.5*G54+G55+G56+G57+G58+G59+G60+G61+G62+G63+G64+G65+G66*0.5)/12 -> 30902.417 | M60: =E60/J60 -> 1.1104164 | N60: =F60/K60 -> 1.1391647 | O60: =G60/L60 -> 1.1246693
...

Sheet Promedios
A3: Etiquetas de fila | B3: Promedio de índice estacional salidas | C3: Promedio de índice estacional llegadas | D3: Promedio de índice estacional total
A4: Ene | B4: 0.74358788 | C4: 0.68403393 | D4: 0.71393613
A5: Feb | B5: 0.75719911 | C5: 0.75695929 | D5: 0.75704322
A6: Mar | B6: 0.99245766 | C6: 0.96984143 | D6: 0.98119281
A7: Abr | B7: 1.04225 | C7: 1.0565451 | D7: 1.0493758
A8: May | B8: 0.89211971 | C8: 0.92270124 | D8: 0.9073557
A9: Jun | B9: 1.0518865 | C9: 0.98312287 | D9: 1.0176585
A10: Jul | B10: 1.3678507 | C10: 1.3282056 | D10: 1.3480227
A11: Ago | B11: 1.4155537 | C11: 1.4323408 | D11: 1.4239157
A12: Sep | B12: 1.0916914 | C12: 1.1601595 | D12: 1.1258202
A13: Oct | B13: 0.97593269 | C13: 0.98503535 | D13: 0.98047812
A14: Nov | B14: 0.7928688 | C14: 0.77084568 | D14: 0.78191285
A15: Dic | B15: 0.84778507 | C15: 0.9192825 | D15: 0.88341569
A16: Total general | B16: 1.0013082 | C16: 1.0013713 | D16: 1.001339
A18: SUMA | B18: =SUM(B4:B15) -> 11.971183 | C18: =SUM(C4:C15) -> 11.969073 | D18: =SUM(D4:D15) -> 11.970127

Sheet Media móvil total
A1: Año | B1: Mes | C1: Trimestre | D1: Media móvil total
A2: 25 | B2: Oct | C2: T4 | D2: 59066.417
A3: 25 | B3: Sep | C3: T3 | D3: 59187.542
A4: 25 | B4: Ago | C4: T3 | D4: 59133.417
A5: 25 | B5: Jul | C5: T3 | D5: 59053.375
A6: 25 | B6: Jun | C6: T2 | D6: 59100.75
A7: 25 | B7: May | C7: T2 | D7: 59262.25
A8: 25 | B8: Abr | C8: T2 | D8: 59101.292
A9: 25 | B9: Mar | C9: T1 | D9: 58977.875
A10: 25 | B10: Feb | C10: T1 | D10: 58917.333
A11: 25 | B11: Ene | C11: T1 | D11: 58610.25
A12: 24 | B12: Dic | C12: T4 | D12: 58574.417
A13: 24 | B13: Nov | C13: T4 | D13: 58550.625
... A233: 4 | B233: jul | C233: T3 | D233: 17570.083

Sheet PIB
A1: Año | B1: Trimestre | C1: Total | D1: Salidas | E1: Llegadas | F1: PIB | G1: Total | H1: Salidas | I1: Llegadas | J1: PIB | K1: TAM
A2: 25 | B2: T4 | C2: 59066.417 | D2: ='Análisis tendencia'!J11 -> 29620.417 | E2: ='Análisis tendencia'!K11 -> 29446 | F2: 128.152 | G2: =LN(C2) -> 10.986418 | H2: =LN(D2) -> 10.296219 | I2: =LN(E2) -> 10.290313 | J2: =LN(F2) -> 4.8532171 | L2: =SLOPE(G2:G79,J2:J79) -> 1.0718369 | M2: elasticidad
A3: 25 | B3: T3 | C3: 177374.33 | D3: =SUM(OFFSET('Análisis tendencia'!$J$12, (ROW(A1)-1)*3, 0, 3, 1)) -> 89029.792 | E3: =SUM(OFFSET('Análisis tendencia'!$K$12, (ROW(A1)-1)*3, 0, 3, 1)) -> 88344.542 | F3: 123.1465 | G3: =LN(C3) -> 12.086018 | H3: =LN(D3) -> 11.396726 | I3: =LN(E3) -> 11.389 | J3: =LN(F3) -> 4.8133747
A4: 25 | B4: T2 | C4: 177464.29 | D4: =SUM(OFFSET('Análisis tendencia'!$J$12, (ROW(A2)-1)*3, 0, 3, 1)) -> 89067.833 | E4: =SUM(OFFSET('Análisis tendencia'!$K$12, (ROW(A2)-1)*3, 0, 3, 1)) -> 88396.458 | F4: 124.2348 | G4: =LN(C4) -> 12.086525 | H4: =LN(D4) -> 11.397154 | I4: =LN(E4) -> 11.389587 | J4: =LN(F4) -> 4.8221733
A5: 25 | B5: T1 | C5: 176505.46 | D5: =SUM(OFFSET('Análisis tendencia'!$J$12, (ROW(A3)-1)*3, 0, 3, 1)) -> 88522.333 | E5: =SUM(OFFSET('Análisis tendencia'!$K$12, (ROW(A3)-1)*3, 0, 3, 1)) -> 87983.125 | F5: 118.6423 | G5: =LN(C5) -> 12.081107 | H5: =LN(D5) -> 11.39101 | I5: =LN(E5) -> 11.3849 | J5: =LN(F5) -> 4.7761131 | K5: =+LN(SUM(C2:C5)) -> 13.288573
A6: 24 | B6: T4 | C6: 175159.12 | D6: =SUM(OFFSET('Análisis tendencia'!$J$12, (ROW(A4)-1)*3, 0, 3, 1)) -> 87812.125 | E6: =SUM(OFFSET('Análisis tendencia'!$K$12, (ROW(A4)-1)*3, 0, 3, 1)) -> 87347 | F6: 124.6174 | G6: =LN(C6) -> 12.07345 | H6: =LN(D6) -> 11.382955 | I6: =LN(E6) -> 11.377644 | J6: =LN(F6) -> 4.8252482 | K6: =+LN(SUM(C3:C6)) -> 13.468083
A7: 24 | B7: T3 | C7: 173406.88 | D7: =SUM(OFFSET('Análisis tendencia'!$J$12, (ROW(A5)-1)*3, 0, 3, 1)) -> 86807.208 | E7: =SUM(OFFSET('Análisis tendencia'!$K$12, (ROW(A5)-1)*3, 0, 3, 1)) -> 86599.667 | F7: 120.1353 | G7: =LN(C7) -> 12.063396 | H7: =LN(D7) -> 11.371445 | I7: =LN(E7) -> 11.369051 | J7: =LN(F7) -> 4.7886186 | K7: =+LN(SUM(C4:C7)) -> 13.462452
A8: 24 | B8: T2 | C8: 171539.79 | D8: =SUM(OFFSET('Análisis tendencia'!$J$12, (ROW(A6)-1)*3, 0, 3, 1)) -> 85984.208 | E8: =SUM(OFFSET('Análisis tendencia'!$K$12, (ROW(A6)-1)*3, 0, 3, 1)) -> 85555.583 | F8: 121.2143 | G8: =LN(C8) -> 12.052571 | H8: =LN(D8) -> 11.361919 | I8: =LN(E8) -> 11.356922 | J8: =LN(F8) -> 4.7975601 | K8: =+LN(SUM(C5:C8)) -> 13.453983
A9: 24 | B9: T1 | C9: 169796.38 | D9: =SUM(OFFSET('Análisis tendencia'!$J$12, (ROW(A7)-1)*3, 0, 3, 1)) -> 85273.083 | E9: =SUM(OFFSET('Análisis tendencia'!$K$12, (ROW(A7)-1)*3, 0, 3, 1)) -> 84523.292 | F9: 115.723 | G9: =LN(C9) -> 12.042355 | H9: =LN(D9) -> 11.353614 | I9: =LN(E9) -> 11.344782 | J9: =LN(F9) -> 4.7511994 | K9: =+LN(SUM(C6:C9)) -> 13.444305
A10: 23 | B10: T4 | C10: 169009.12 | D10: =SUM(OFFSET('Análisis tendencia'!$J$12, (ROW(A8)-1)*3, 0, 3, 1)) -> 84905.125 | E10: =SUM(OFFSET('Análisis tendencia'!$K$12, (ROW(A8)-1)*3, 0, 3, 1)) -> 84104 | F10: 120.1663 | G10: =LN(C10) -> 12.037708 | H10: =LN(D10) -> 11.34929 | I10: =LN(E10) -> 11.339809 | J10: =LN(F10) -> 4.7888766 | K10: =+LN(SUM(C7:C10)) -> 13.435351
A11: 23 | B11: T3 | C11: 169681.75 | D11: =SUM(OFFSET('Análisis tendencia'!$J$12, (ROW(A9)-1)*3, 0, 3, 1)) -> 85295.167 | E11: =SUM(OFFSET('Análisis tendencia'!$K$12, (ROW(A9)-1)*3, 0, 3, 1)) -> 84386.583 | F11: 115.7636 | G11: =LN(C11) -> 12.04168 | H11: =LN(D11) -> 11.353873 | I11: =LN(E11) -> 11.343164 | J11: =LN(F11) -> 4.7515502 | K11: =+LN(SUM(C8:C11)) -> 13.429888
A12: 23 | B12: T2 | C12: 172825.54 | D12: =SUM(OFFSET('Análisis tendencia'!$J$12, (ROW(A10)-1)*3, 0, 3, 1)) -> 86681.375 | E12: =SUM(OFFSET('Análisis tendencia'!$K$12, (ROW(A10)-1)*3, 0, 3, 1)) -> 86144.167 | F12: 116.4037 | G12: =LN(C12) -> 12.060038 | H12: =LN(D12) -> 11.369994 | I12: =LN(E12) -> 11.363778 | J12: =LN(F12) -> 4.7570643 | K12: =+LN(SUM(C9:C12)) -> 13.431777
A13: 23 | B13: T1 | C13: 173036.12 | D13: =SUM(OFFSET('Análisis tendencia'!$J$12, (ROW(A11)-1)*3, 0, 3, 1)) -> 86837.667 | E13: =SUM(OFFSET('Análisis tendencia'!$K$12, (ROW(A11)-1)*3, 0, 3, 1)) -> 86198.458 | F13: 112.2953 | G13: =LN(C13) -> 12.061256 | H13: =LN(D13) -> 11.371796 | I13: =LN(E13) -> 11.364408 | J13: =LN(F13) -> 4.721132 | K13: =+LN(SUM(C10:C13)) -> 13.436521
A14: 22 | B14: T4 | C14: 172401.08 | D14: =SUM(OFFSET('Análisis tendencia'!$J$12, (ROW(A12)-1)*3, 0, 3, 1)) -> 86665.042 | E14: =SUM(OFFSET('Análisis tendencia'!$K$12, (ROW(A12)-1)*3, 0, 3, 1)) -> 85736.042 | F14: 117.7441 | G14: =LN(C14) -> 12.057579 | H14: =LN(D14) -> 11.369806 | I14: =LN(E14) -> 11.359029 | J14: =LN(F14) -> 4.7685136 | K14: =+LN(SUM(C11:C14)) -> 13.441463
A15: 22 | B15: T3 | C15: 164647.46 | D15: =SUM(OFFSET('Análisis tendencia'!$J$12, (ROW(A13)-1)*3, 0, 3, 1)) -> 82809.875 | E15: =SUM(OFFSET('Análisis tendencia'!$K$12, (ROW(A13)-1)*3, 0, 3, 1)) -> 81837.583 | F15: 114.0324 | G15: =LN(C15) -> 12.011562 | H15: =LN(D15) -> 11.324303 | I15: =LN(E15) -> 11.312492 | J15: =LN(F15) -> 4.7364826 | K15: =+LN(SUM(C12:C15)) -> 13.434119
A16: 22 | B16: T2 | C16: 147673.75 | D16: =SUM(OFFSET('Análisis tendencia'!$J$12, (ROW(A14)-1)*3, 0, 3, 1)) -> 74458.667 | E16: =SUM(OFFSET('Análisis tendencia'!$K$12, (ROW(A14)-1)*3, 0, 3, 1)) -> 73215.083 | F16: 114.3184 | G16: =LN(C16) -> 11.902761 | H16: =LN(D16) -> 11.217999 | I16: =LN(E16) -> 11.201157 | J16: =LN(F16) -> 4.7389875 | K16: =+LN(SUM(C13:C16)) -> 13.396593
... A23: 18 | B23: T3 | C23: 119337.79 | D23: =SUM(OFFSET('Análisis tendencia'!$J$12, (ROW(A21)-1)*3, 0, 3, 1)) -> 60036.208 | E23: =SUM(OFFSET('Análisis tendencia'!$K$12, (ROW(A21)-1)*3, 0, 3, 1)) -> 59301.583 | F23: 109.6224 | G23: =LN(C23) -> 11.689713 | H23: =LN(D23) -> 11.002703 | I23: =LN(E23) -> 10.990391 | J23: =LN(F23) -> 4.6970417 | K23: =+LN(SUM(C20:C23)) -> 12.942727
A24: 18 | B24: T2 | C24: 120875 | D24: =SUM(OFFSET('Análisis tendencia'!$J$12, (ROW(A22)-1)*3, 0, 3, 1)) -> 60931.208 | E24: =SUM(OFFSET('Análisis tendencia'!$K$12, (ROW(A22)-1)*3, 0, 3, 1)) -> 59943.792 | F24: 111.7631 | G24: =LN(C24) -> 11.702512 | H24: =LN(D24) -> 11.017501 | I24: =LN(E24) -> 11.001163 | J24: =LN(F24) -> 4.7163815 | K24: =+LN(SUM(C21:C24)) -> 13.018055 | M24: Tasa de Crecimiento Anual Compuesta (CAGR):
A25: 18 | B25: T1 | C25: 115887.79 | D25: =SUM(OFFSET('Análisis tendencia'!$J$12, (ROW(A23)-1)*3, 0, 3, 1)) -> 58388.75 | E25: =SUM(OFFSET('Análisis tendencia'!$K$12, (ROW(A23)-1)*3, 0, 3, 1)) -> 57499.042 | F25: 105.3824 | G25: =LN(C25) -> 11.660378 | H25: =LN(D25) -> 10.974879 | I25: =LN(E25) -> 10.959524 | J25: =LN(F25) -> 4.6575956 | K25: =+LN(SUM(C22:C25)) -> 13.056139
A26: 17 | B26: T4 | C26: 109668.67 | D26: =SUM(OFFSET('Análisis tendencia'!$J$12, (ROW(A24)-1)*3, 0, 3, 1)) -> 55160.583 | E26: =SUM(OFFSET('Análisis tendencia'!$K$12, (ROW(A24)-1)*3, 0, 3, 1)) -> 54508.083 | F26: 110.9135 | G26: =LN(C26) -> 11.605219 | H26: =LN(D26) -> 10.918004 | I26: =LN(E26) -> 10.906104 | J26: =LN(F26) -> 4.7087506 | K26: =+LN(SUM(C23:C26)) -> 13.051446
A27: 17 | B27: T3 | C27: 109727.33 | D27: =SUM(OFFSET('Análisis tendencia'!$J$12, (ROW(A25)-1)*3, 0, 3, 1)) -> 55123.5 | E27: =SUM(OFFSET('Análisis tendencia'!$K$12, (ROW(A25)-1)*3, 0, 3, 1)) -> 54603.833 | F27: 107.4891 | G27: =LN(C27) -> 11.605754 | H27: =LN(D27) -> 10.917331 | I27: =LN(E27) -> 10.907859 | J27: =LN(F27) -> 4.6773894 | K27: =+LN(SUM(C24:C27)) -> 13.030596
A28: 17 | B28: T2 | C28: 109588.12 | D28: =SUM(OFFSET('Análisis tendencia'!$J$12, (ROW(A26)-1)*3, 0, 3, 1)) -> 55116.708 | E28: =SUM(OFFSET('Análisis tendencia'!$K$12, (ROW(A26)-1)*3, 0, 3, 1)) -> 54471.417 | F28: 109.0386 | G28: =LN(C28) -> 11.604484 | H28: =LN(D28) -> 10.917208 | I28: =LN(E28) -> 10.905431 | J28: =LN(F28) -> 4.6917019 | K28: =+LN(SUM(C25:C28)) -> 13.005542
A29: 17 | B29: T1 | C29: 107226.88 | D29: =SUM(OFFSET('Análisis tendencia'!$J$12, (ROW(A27)-1)*3, 0, 3, 1)) -> 54129.875 | E29: =SUM(OFFSET('Análisis tendencia'!$K$12, (ROW(A27)-1)*3, 0, 3, 1)) -> 53097 | F29: 102.7508 | G29: =LN(C29) -> 11.582702 | H29: =LN(D29) -> 10.899142 | I29: =LN(E29) -> 10.879876 | J29: =LN(F29) -> 4.6323066 | K29: =+LN(SUM(C26:C29)) -> 12.985881
A30: 16 | B30: T4 | C30: 104556.88 | D30: =SUM(OFFSET('Análisis tendencia'!$J$12, (ROW(A28)-1)*3, 0, 3, 1)) -> 52787.5 | E30: =SUM(OFFSET('Análisis tendencia'!$K$12, (ROW(A28)-1)*3, 0, 3, 1)) -> 51769.375 | F30: 107.5364 | G30: =LN(C30) -> 11.557486 | H30: =LN(D30) -> 10.87403 | I30: =LN(E30) -> 10.854554 | J30: =LN(F30) -> 4.6778294 | K30: =+LN(SUM(C27:C30)) -> 12.974094
A31: 16 | B31: T3 | C31: 103969.5 | D31: =SUM(OFFSET('Análisis tendencia'!$J$12, (ROW(A29)-1)*3, 0, 3, 1)) -> 52549.583 | E31: =SUM(OFFSET('Análisis tendencia'!$K$12, (ROW(A29)-1)*3, 0, 3, 1)) -> 51419.917 | F31: 104.4333 | G31: =LN(C31) -> 11.551853 | H31: =LN(D31) -> 10.869512 | I31: =LN(E31) -> 10.847781 | J31: =LN(F31) -> 4.6485486 | K31: =+LN(SUM(C28:C31)) -> 12.960647 | M31: Vfinal (PIB 2025 T4): | O31: =F2 -> 128.152
A32: 16 | B32: T2 | C32: 104497.25 | D32: =SUM(OFFSET('Análisis tendencia'!$J$12, (ROW(A30)-1)*3, 0, 3, 1)) -> 52815.708 | E32: =SUM(OFFSET('Análisis tendencia'!$K$12, (ROW(A30)-1)*3, 0, 3, 1)) -> 51681.542 | F32: 105.6803 | G32: =LN(C32) -> 11.556916 | H32: =LN(D32) -> 10.874564 | I32: =LN(E32) -> 10.852856 | J32: =LN(F32) -> 4.6604185 | K32: =+LN(SUM(C29:C32)) -> 12.948606 | M32: Vinicial (PIB 2004 T1): | O32: =F79 -> 91.9887
A33: 16 | B33: T1 | C33: 105645.21 | D33: =SUM(OFFSET('Análisis tendencia'!$J$12, (ROW(A31)-1)*3, 0, 3, 1)) -> 53368.667 | E33: =SUM(OFFSET('Análisis tendencia'!$K$12, (ROW(A31)-1)*3, 0, 3, 1)) -> 52276.542 | F33: 100.434 | G33: =LN(C33) -> 11.567842 | H33: =LN(D33) -> 10.884979 | I33: =LN(E33) -> 10.864303 | J33: =LN(F33) -> 4.6095008 | K33: =+LN(SUM(C30:C33)) -> 12.944836
A34: 15 | B34: T4 | C34: 106111.71 | D34: =SUM(OFFSET('Análisis tendencia'!$J$12, (ROW(A32)-1)*3, 0, 3, 1)) -> 53628.667 | E34: =SUM(OFFSET('Análisis tendencia'!$K$12, (ROW(A32)-1)*3, 0, 3, 1)) -> 52483.042 | F34: 105.3563 | G34: =LN(C34) -> 11.572248 | H34: =LN(D34) -> 10.889839 | I34: =LN(E34) -> 10.868245 | J34: =LN(F34) -> 4.6573479 | K34: =+LN(SUM(C31:C34)) -> 12.948542 | M34: t (tiempo) | N34: =COUNT(A2:A79) -> 78 | O34: trimestres + 8 de los años 2020 y 2021
A35: 15 | B35: T3 | C35: 105983.62 | D35: =SUM(OFFSET('Análisis tendencia'!$J$12, (ROW(A33)-1)*3, 0, 3, 1)) -> 53569.75 | E35: =SUM(OFFSET('Análisis tendencia'!$K$12, (ROW(A33)-1)*3, 0, 3, 1)) -> 52413.875 | F35: 101.5296 | G35: =LN(C35) -> 11.57104 | H35: =LN(D35) -> 10.88874 | I35: =LN(E35) -> 10.866927 | J35: =LN(F35) -> 4.6203504 | K35: =+LN(SUM(C32:C35)) -> 12.953324 | M35: trimestres | N35: =N34+8 -> 86 | S35: PAX2025 | T35: =SUM('Comparativa mes año anterior'!H9:H20) -> 707493
A36: 15 | B36: T2 | C36: 106989.29 | D36: =SUM(OFFSET('Análisis tendencia'!$J$12, (ROW(A34)-1)*3, 0, 3, 1)) -> 54156.792 | E36: =SUM(OFFSET('Análisis tendencia'!$K$12, (ROW(A34)-1)*3, 0, 3, 1)) -> 52832.5 | F36: 102.4213 | G36: =LN(C36) -> 11.580484 | H36: =LN(D36) -> 10.899639 | I36: =LN(E36) -> 10.874882 | J36: =LN(F36) -> 4.6290947 | K36: =+LN(SUM(C33:C36)) -> 12.959209 | M36: años | N36: =N35/4 -> 21.5
A37: 15 | B37: T1 | C37: 106939.54 | D37: =SUM(OFFSET('Análisis tendencia'!$J$12, (ROW(A35)-1)*3, 0, 3, 1)) -> 54099.917 | E37: =SUM(OFFSET('Análisis tendencia'!$K$12, (ROW(A35)-1)*3, 0, 3, 1)) -> 52839.625 | F37: 96.9342 | G37: =LN(C37) -> 11.580019 | H37: =LN(D37) -> 10.898588 | I37: =LN(E37) -> 10.875017 | J37: =LN(F37) -> 4.5740324 | K37: =+LN(SUM(C34:C37)) -> 12.962251
A38: 14 | B38: T4 | C38: 105809.92 | D38: =SUM(OFFSET('Análisis tendencia'!$J$12, (ROW(A36)-1)*3, 0, 3, 1)) -> 53504.5 | E38: =SUM(OFFSET('Análisis tendencia'!$K$12, (ROW(A36)-1)*3, 0, 3, 1)) -> 52305.417 | F38: 101.1428 | G38: =LN(C38) -> 11.5694 | H38: =LN(D38) -> 10.887521 | I38: =LN(E38) -> 10.864855 | J38: =LN(F38) -> 4.6165334 | K38: =+LN(SUM(C35:C38)) -> 12.961543 | M38: r= | N38: =(O31/O32)^(1/N36)-1 -> 0.015540508
A39: 14 | B39: T3 | C39: 104660.46 | D39: =SUM(OFFSET('Análisis tendencia'!$J$12, (ROW(A37)-1)*3, 0, 3, 1)) -> 52839.583 | E39: =SUM(OFFSET('Análisis tendencia'!$K$12, (ROW(A37)-1)*3, 0, 3, 1)) -> 51820.875 | F39: 97.2901 | G39: =LN(C39) -> 11.558477 | H39: =LN(D39) -> 10.875016 | I39: =LN(E39) -> 10.855548 | J39: =LN(F39) -> 4.5776972 | K39: =+LN(SUM(C36:C39)) -> 12.95843 | R39: i | T39: PAX
A40: 14 | B40: T2 | C40: 104024.25 | D40: =SUM(OFFSET('Análisis tendencia'!$J$12, (ROW(A38)-1)*3, 0, 3, 1)) -> 52411.375 | E40: =SUM(OFFSET('Análisis tendencia'!$K$12, (ROW(A38)-1)*3, 0, 3, 1)) -> 51612.875 | F40: 98.3013 | G40: =LN(C40) -> 11.552379 | H40: =LN(D40) -> 10.866879 | I40: =LN(E40) -> 10.851526 | J40: =LN(F40) -> 4.5880373 | K40: =+LN(SUM(C37:C40)) -> 12.951419 | M40: 1.Escenario Pesimista (Bajo):PIB crece al 1,0% | R40: =L2*1/100 -> 0.010718369 | T40: =T35*(1+(R40))^(2050-2025) -> 923583.4
A41: 14 | B41: T1 | C41: 104403.21 | D41: =SUM(OFFSET('Análisis tendencia'!$J$12, (ROW(A39)-1)*3, 0, 3, 1)) -> 52532.083 | E41: =SUM(OFFSET('Análisis tendencia'!$K$12, (ROW(A39)-1)*3, 0, 3, 1)) -> 51871.125 | F41: 93.6541 | G41: =LN(C41) -> 11.556016 | H41: =LN(D41) -> 10.869179 | I41: =LN(E41) -> 10.856518 | J41: =LN(F41) -> 4.5396082 | K41: =+LN(SUM(C38:C41)) -> 12.945382 | M41: 2.Escenario Base (Medio): PIB crece al 1,5% | R41: =L2*1.5/100 -> 0.016077554 | T41: =T35*(1+(R41))^(2050-2025) -> 1054128.6
A42: 13 | B42: T4 | C42: 106364 | D42: =SUM(OFFSET('Análisis tendencia'!$J$12, (ROW(A40)-1)*3, 0, 3, 1)) -> 53411.25 | E42: =SUM(OFFSET('Análisis tendencia'!$K$12, (ROW(A40)-1)*3, 0, 3, 1)) -> 52952.75 | F42: 98.6692 | G42: =LN(C42) -> 11.574622 | H42: =LN(D42) -> 10.885777 | I42: =LN(E42) -> 10.877155 | J42: =LN(F42) -> 4.5917728 | K42: =+LN(SUM(C39:C42)) -> 12.946704 | M42: 3.Escenario Optimista (Alto): PIB crece al 2,2% | R42: =L2*N38 -> 0.016656891 | T42: =T35*(1+(R42))^(2050-2025) -> 1069257.6
A43: 13 | B43: T3 | C43: 111302.25 | D43: =SUM(OFFSET('Análisis tendencia'!$J$12, (ROW(A41)-1)*3, 0, 3, 1)) -> 55793.083 | E43: =SUM(OFFSET('Análisis tendencia'!$K$12, (ROW(A41)-1)*3, 0, 3, 1)) -> 55509.167 | F43: 95.5361 | G43: =LN(C43) -> 11.620005 | H43: =LN(D43) -> 10.929405 | I43: =LN(E43) -> 10.924303 | J43: =LN(F43) -> 4.5595042 | K43: =+LN(SUM(C40:C43)) -> 12.962415
A44: 13 | B44: T2 | C44: 117364.33 | D44: =SUM(OFFSET('Análisis tendencia'!$J$12, (ROW(A42)-1)*3, 0, 3, 1)) -> 58790.667 | E44: =SUM(OFFSET('Análisis tendencia'!$K$12, (ROW(A42)-1)*3, 0, 3, 1)) -> 58573.667 | F44: 97.4212 | G44: =LN(C44) -> 11.673038 | H44: =LN(D44) -> 10.981738 | I44: =LN(E44) -> 10.978041 | J44: =LN(F44) -> 4.5790438 | K44: =+LN(SUM(C41:C44)) -> 12.993242
A45: 13 | B45: T1 | C45: 124894.25 | D45: =SUM(OFFSET('Análisis tendencia'!$J$12, (ROW(A43)-1)*3, 0, 3, 1)) -> 62358.208 | E45: =SUM(OFFSET('Análisis tendencia'!$K$12, (ROW(A43)-1)*3, 0, 3, 1)) -> 62536.042 | F45: 92.9149 | G45: =LN(C45) -> 11.735223 | H45: =LN(D45) -> 11.040651 | I45: =LN(E45) -> 11.043498 | J45: =LN(F45) -> 4.531684 | K45: =+LN(SUM(C42:C45)) -> 13.038818
A46: 12 | B46: T4 | C46: 129677.88 | D46: =SUM(OFFSET('Análisis tendencia'!$J$12, (ROW(A44)-1)*3, 0, 3, 1)) -> 64679.208 | E46: =SUM(OFFSET('Análisis tendencia'!$K$12, (ROW(A44)-1)*3, 0, 3, 1)) -> 64998.667 | F46: 99.1976 | G46: =LN(C46) -> 11.772809 | H46: =LN(D46) -> 11.077195 | I46: =LN(E46) -> 11.082122 | J46: =LN(F46) -> 4.5971138 | K46: =+LN(SUM(C43:C46)) -> 13.088266
...

Sheet HP
A3: Etiquetas de fila | B3: Promedio de índice estacional salidas | C3: Promedio de índice estacional llegadas | D3: Promedio de índice estacional total | E3: MMT1% | F3: MMT1.5% | G3: MMT2.2% | H3: DMT1% | I3: DMT1.5% | J3: DMT2.2% | K3: HDP1% | L3: HDP1.5% | M3: HDP2.2%
A4: Ene | B4: 0.74358788 | C4: 0.68403393 | D4: 0.71393613 | E4: =$F$20*D4/12 -> 54948.297 | F4: =$F$21*D4/12 -> 62715.04 | G4: =$F$22*D4/12 -> 63615.139 | H4: =+E4/31 -> 1772.5257 | I4: =+F4/31 -> 2023.0658 | J4: =+G4/31 -> 2052.1013 | K4: =+H4*0.11 -> 194.97783 | L4: =+I4*0.11 -> 222.53724 | M4: =+J4*0.11 -> 225.73114
A5: Feb | B5: 0.75719911 | C5: 0.75695929 | D5: 0.75704322 | E5: =$F$20*D5/12 -> 58266.046 | F5: =$F$21*D5/12 -> 66501.741 | G5: =$F$22*D5/12 -> 67456.187 | H5: =+E5/31 -> 1879.5499 | I5: =+F5/31 -> 2145.2174 | J5: =+G5/31 -> 2176.006 | K5: =+H5*0.11 -> 206.75049 | L5: =+I5*0.11 -> 235.97392 | M5: =+J5*0.11 -> 239.36066
A6: Mar | B6: 0.99245766 | C6: 0.96984143 | D6: 0.98119281 | E6: =$F$20*D6/12 -> 75517.782 | F6: =$F$21*D6/12 -> 86191.947 | G6: =$F$22*D6/12 -> 87428.992 | H6: =+E6/31 -> 2436.0575 | I6: =+F6/31 -> 2780.3854 | J6: =+G6/31 -> 2820.2901 | K6: =+H6*0.11 -> 267.96632 | L6: =+I6*0.11 -> 305.84239 | M6: =+J6*0.11 -> 310.23191
A7: Abr | B7: 1.04225 | C7: 1.0565451 | D7: 1.0493758 | E7: =$F$20*D7/12 -> 80765.509 | F7: =$F$21*D7/12 -> 92181.421 | G7: =$F$22*D7/12 -> 93504.428 | H7: =+E7/31 -> 2605.339 | I7: =+F7/31 -> 2973.5942 | J7: =+G7/31 -> 3016.2719 | K7: =+H7*0.11 -> 286.58729 | L7: =+I7*0.11 -> 327.09537 | M7: =+J7*0.11 -> 331.78991
A8: May | B8: 0.89211971 | C8: 0.92270124 | D8: 0.9073557 | E8: =$F$20*D8/12 -> 69834.888 | F8: =$F$21*D8/12 -> 79705.797 | G8: =$F$22*D8/12 -> 80849.751 | H8: =+E8/31 -> 2252.7383 | I8: =+F8/31 -> 2571.1547 | J8: =+G8/31 -> 2608.0565 | K8: =+H8*0.11 -> 247.80122 | L8: =+I8*0.11 -> 282.82702 | M8: =+J8*0.11 -> 286.88621
A9: Jun | B9: 1.0518865 | C9: 0.98312287 | D9: 1.0176585 | E9: =$F$20*D9/12 -> 78324.372 | F9: =$F$21*D9/12 -> 89395.238 | G9: =$F$22*D9/12 -> 90678.257 | H9: =+E9/31 -> 2526.5926 | I9: =+F9/31 -> 2883.7174 | J9: =+G9/31 -> 2925.1051 | K9: =+H9*0.11 -> 277.92519 | L9: =+I9*0.11 -> 317.20891 | M9: =+J9*0.11 -> 321.76156
A10: Jul | B10: 1.3678507 | C10: 1.3282056 | D10: 1.3480227 | E10: =$F$20*D10/12 -> 103750.95 | F10: =$F$21*D10/12 -> 118415.77 | G10: =$F$22*D10/12 -> 120115.3 | H10: =+E10/31 -> 3346.8048 | I10: =+F10/31 -> 3819.8636 | J10: =+G10/31 -> 3874.687 | K10: =+H10*0.11 -> 368.14853 | L10: =+I10*0.11 -> 420.18499 | M10: =+J10*0.11 -> 426.21557
A11: Ago | B11: 1.4155537 | C11: 1.4323408 | D11: 1.4239157 | E11: =$F$20*D11/12 -> 109592.08 | F11: =$F$21*D11/12 -> 125082.52 | G11: =$F$22*D11/12 -> 126877.73 | H11: =+E11/31 -> 3535.2283 | I11: =+F11/31 -> 4034.92 | J11: =+G11/31 -> 4092.83 | K11: =+H11*0.11 -> 388.87511 | L11: =+I11*0.11 -> 443.8412 | M11: =+J11*0.11 -> 450.2113
A12: Sep | B12: 1.0916914 | C12: 1.1601595 | D12: 1.1258202 | E12: =$F$20*D12/12 -> 86649.07 | F12: =$F$21*D12/12 -> 98896.602 | G12: =$F$22*D12/12 -> 100315.99 | H12: =+E12/31 -> 2795.1313 | I12: =+F12/31 -> 3190.213 | J12: =+G12/31 -> 3235.9996 | K12: =+H12*0.11 -> 307.46444 | L12: =+I12*0.11 -> 350.92343 | M12: =+J12*0.11 -> 355.95995
A13: Oct | B13: 0.97593269 | C13: 0.98503535 | D13: 0.98047812 | E13: =$F$20*D13/12 -> 75462.776 | F13: =$F$21*D13/12 -> 86129.166 | G13: =$F$22*D13/12 -> 87365.31 | H13: =+E13/31 -> 2434.2831 | I13: =+F13/31 -> 2778.3602 | J13: =+G13/31 -> 2818.2358 | K13: =+H13*0.11 -> 267.77114 | L13: =+I13*0.11 -> 305.61962 | M13: =+J13*0.11 -> 310.00594
A14: Nov | B14: 0.7928688 | C14: 0.77084568 | D14: 0.78191285 | E14: =$F$20*D14/12 -> 60180.144 | F14: =$F$21*D14/12 -> 68686.389 | G14: =$F$22*D14/12 -> 69672.191 | H14: =+E14/31 -> 1941.295 | I14: =+F14/31 -> 2215.69 | J14: =+G14/31 -> 2247.49 | K14: =+H14*0.11 -> 213.54245 | L14: =+I14*0.11 -> 243.7259 | M14: =+J14*0.11 -> 247.2239
A15: Dic | B15: 0.84778507 | C15: 0.9192825 | D15: 0.88341569 | E15: =$F$20*D15/12 -> 67992.339 | F15: =$F$21*D15/12 -> 77602.81 | G15: =$F$22*D15/12 -> 78716.582 | H15: =+E15/31 -> 2193.3013 | I15: =+F15/31 -> 2503.3165 | J15: =+G15/31 -> 2539.2446 | K15: =+H15*0.11 -> 241.26314 | L15: =+I15*0.11 -> 275.36481 | M15: =+J15*0.11 -> 279.3169
E19: i | F19: PAX
A20: 1.Escenario Pesimista (Bajo):PIB crece al 1,0% | E20: 0.010718369 | F20: 923583.4
A21: 2.Escenario Base (Medio): PIB crece al 1,5% | E21: 0.016077554 | F21: 1054128.6
A22: 3.Escenario Optimista (Alto): PIB crece al 2,2% | E22: 0.016656891 | F22: 1069257.6

Sheet Tabla1
A1: Columna1
A2: 1050
A3: 1127
A4: 894
A5: 962
A6: 987
A7: 946
A8: 796
A9: 745
A10: 853
A11: 923
A12: 1081
A13: 996
... A45: 646

Sheet Operaciones
F1: Año | G1: Mes | H1: Trimestre | I1: Pasajeros | J1: Operaciones
F2: 26 | G2: Abr | H2: T2 | I2: 63063 | J2: 987 | K2: =+I2/J2 -> 63.893617 | M2: =+AVERAGE(K2:K41) -> 67.420235
A3: Año | B3: Trimestre | C3: Suma de Media móvil total | F3: 26 | G3: Mar | H3: T1 | I3: 53833 | J3: 946 | K3: =+I3/J3 -> 56.90592 | M3: Supongamos una capacidad de 100
A4: 4 | B4: T3 | C4: 54390.958 | F4: 26 | G4: Feb | H4: T1 | I4: 43485 | J4: 796 | K4: =+I4/J4 -> 54.629397 | M4: Supongamos un load factor de 85%
A5: 4 | B5: T4 | C5: 63177.583 | F5: 26 | G5: Ene | H5: T1 | I5: 46335 | J5: 745 | K5: =+I5/J5 -> 62.194631
A6: 5 | B6: T1 | C6: 81786.917 | F6: 25 | G6: Dic | H6: T4 | I6: 51192 | J6: 853 | K6: =+I6/J6 -> 60.014068
A7: 5 | B7: T2 | C7: 100600.54 | F7: 25 | G7: Nov | H7: T4 | I7: 47899 | J7: 923 | K7: =+I7/J7 -> 51.894908 | N7: PIB 1% | O7: PIB 1.5% | P7: PIB 2.2%
A8: 5 | B8: T3 | C8: 109061.67 | F8: 25 | G8: Oct | H8: T4 | I8: 66268 | J8: 1081 | K8: =+I8/J8 -> 61.302498 | N8: 388.87511 | O8: 443.8412 | P8: 450.2113
A9: 5 | B9: T4 | C9: 112000.25 | F9: 25 | G9: Sep | H9: T3 | I9: 63279 | J9: 996 | K9: =+I9/J9 -> 63.533133 | M9: Operaciones | N9: =+N8/(100*0.85) -> 4.5750013 | O9: =+O8/(100*0.85) -> 5.2216611 | P9: =+P8/(100*0.85) -> 5.2966035 | Q9: operaciones/hora
A10: 6 | B10: T1 | C10: 111195.38 | F10: 25 | G10: Ago | H10: T3 | I10: 73934 | J10: 849 | K10: =+I10/J10 -> 87.083628 | M10: Nº pistas | N10: =+N9/40 -> 0.11437503 | O10: =+O9/40 -> 0.13054153 | P10: =+P9/40 -> 0.13241509 | Q10: Para cualquier situación nos vale con una pista
A11: 6 | B11: T2 | C11: 108202.17 | F11: 25 | G11: Jul | H11: T3 | I11: 71064 | J11: 932 | K11: =+I11/J11 -> 76.248927
A12: 6 | B12: T3 | C12: 109786.29 | F12: 25 | G12: Jun | H12: T2 | I12: 61293 | J12: 897 | K12: =+I12/J12 -> 68.331104 | M12: En un aeropuerto se pueden gestionar 40-45 salidas/llegadas a la hora
A13: 6 | B13: T4 | C13: 114748.38 | F13: 25 | G13: May | H13: T2 | I13: 64862 | J13: 982 | K13: =+I13/J13 -> 66.050916
A14: 7 | B14: T1 | C14: 120534.17 | F14: 25 | G14: Abr | H14: T2 | I14: 67643 | J14: 930 | K14: =+I14/J14 -> 72.734409
A15: 7 | B15: T2 | C15: 125247.62 | F15: 25 | G15: Mar | H15: T1 | I15: 52160 | J15: 718 | K15: =+I15/J15 -> 72.64624
A16: 7 | B16: T3 | C16: 129386.29 | F16: 25 | G16: Feb | H16: T1 | I16: 43859 | J16: 673 | K16: =+I16/J16 -> 65.169391
A17: 7 | B17: T4 | C17: 135538.04 | F17: 25 | G17: Ene | H17: T1 | I17: 44040 | J17: 674 | K17: =+I17/J17 -> 65.341246
A18: 8 | B18: T1 | C18: 143762.88 | F18: 24 | G18: Dic | H18: T4 | I18: 54624 | J18: 813 | K18: =+I18/J18 -> 67.188192
A19: 8 | B19: T2 | C19: 148304.29 | F19: 24 | G19: Nov | H19: T4 | I19: 48343 | J19: 931 | K19: =+I19/J19 -> 51.925886
A20: 8 | B20: T3 | C20: 148393.67 | F20: 24 | G20: Oct | H20: T4 | I20: 61961 | J20: 991 | K20: =+I20/J20 -> 62.523713
A21: 8 | B21: T4 | C21: 144857 | F21: 24 | G21: Sep | H21: T3 | I21: 64624 | J21: 957 | K21: =+I21/J21 -> 67.527691
A22: 9 | B22: T1 | C22: 137805.5 | F22: 24 | G22: Ago | H22: T3 | I22: 71136 | J22: 929 | K22: =+I22/J22 -> 76.572659
A23: 9 | B23: T2 | C23: 133044.21 | F23: 24 | G23: Jul | H23: T3 | I23: 66492 | J23: 952 | K23: =+I23/J23 -> 69.844538
A24: 9 | B24: T3 | C24: 131604.42 | F24: 24 | G24: Jun | H24: T2 | I24: 65005 | J24: 905 | K24: =+I24/J24 -> 71.828729
... A41: 13 | B41: T4 | C41: 106364 | F41: 23 | G41: Ene | H41: T1 | I41: 51341 | J41: 646 | K41: =+I41/J41 -> 79.475232
A42: 14 | B42: T1 | C42: 104403.21 | F42: 22 | G42: Dic | H42: T4 | I42: 54341
A43: 14 | B43: T2 | C43: 104024.25 | F43: 22 | G43: Nov | H43: T4 | I43: 44920 | J43: ( no hay datos más antiguos)
A44: 14 | B44: T3 | C44: 104660.46 | F44: 22 | G44: Oct | H44: T4 | I44: 58851
A45: 14 | B45: T4 | C45: 105809.92 | F45: 22 | G45: Sep | H45: T3 | I45: 61279
A46: 15 | B46: T1 | C46: 106939.54 | F46: 22 | G46: Ago | H46: T3 | I46: 72152
A47: 15 | B47: T2 | C47: 106989.29 | F47: 22 | G47: Jul | H47: T3 | I47: 69483
A48: 15 | B48: T3 | C48: 105983.62 | F48: 22 | G48: Jun | H48: T2 | I48: 62259
A49: 15 | B49: T4 | C49: 106111.71 | F49: 22 | G49: May | H49: T2 | I49: 51083
A50: 16 | B50: T1 | C50: 105645.21 | F50: 22 | G50: Abr | H50: T2 | I50: 52954
A51: 16 | B51: T2 | C51: 104497.25 | F51: 22 | G51: Mar | H51: T1 | I51: 44619
A52: 16 | B52: T3 | C52: 103969.5 | F52: 22 | G52: Feb | H52: T1 | I52: 29622
A53: 16 | B53: T4 | C53: 104556.88 | F53: 22 | G53: Ene | H53: T1 | I53: 26274
A54: 17 | B54: T1 | C54: 107226.88 | F54: 19 | G54: dic | H54: T4 | I54: 28098
A55: 17 | B55: T2 | C55: 109588.12 | F55: 19 | G55: nov | H55: T4 | I55: 24240
... A81: 25 | B81: T4 | C81: 59066.417 | F81: 17 | G81: sep | H81: T3 | I81: 42155
...
